<?xml version="1.0"?>
<robot xmlns:xacro="http://www.ros.org/wiki/xacro">
    
    <!-- BASE_LINK -->
    <link name="base_footprint">
       <origin xyz="0.0 0.0 0.0"/>
    </link>

    <joint name="base_joint" type="fixed">
        <origin xyz="0.0 0.0 0.05"/>    <!-- tam 2 banh cach mat dat 5cm -->
        <parent link="base_footprint"/>
        <child link="base_link"/>
    </joint>

    <link name="base_link">
       <origin xyz="0.0 0.0 0.0"/>
    </link>

    <!-- CHASSIS_LINK -->

    <joint name="chassis_joint" type="fixed">
        <parent link="base_link"/>
        <child link="chassis"/>
        <origin xyz="0.07 0.0 0.02"/>    <!-- 7cm -->
    </joint>

    <link name="chassis">
        <inertial>
            <origin xyz="-0.2 0.0 0.088" rpy="0.0 0.0 0.0"/> <!-- lui 20cm nang 6.8cm -->
            <mass value="10.0"/>
            <inertia ixx="0.1" ixy="0.0" ixz="0.0" iyy="0.1" iyz="0.0" izz="0.1"/>
        </inertial>
        <visual>
            <origin xyz="-0.2 0.0 0.088" rpy="0.0 0.0 0.0"/>
            <geometry>
                <box size="0.4 0.4 0.18"/>
            </geometry>
            <material name="white"/>
        </visual>
        <collision>
            <origin xyz="-0.2 0.0 0.088" rpy="0.0 0.0 0.0"/>
            <geometry>
                <box size="0.4 0.4 0.18"/>
            </geometry>
        </collision>
    </link>

    <gazebo reference="chassis">
        <material>Gazebo/Write</material>
    </gazebo>

    <!-- LEFT WHEEL LINK -->
    <joint name="left_wheel_joint" type="continuous">
        <origin xyz="0 0.161 0" rpy="-${pi/2} 0.0 0.0"/> <!-- cach tam 16.1cm -->
        <parent link="base_link"/>
        <child link="left_wheel"/>
        <axis xyz="0.0 0.0 1.0"/>
    </joint> 

    <link name="left_wheel">
        <visual>
            <origin xyz="0.0 0.0 0.0" rpy="0.0 0.0 0.0"/>
            <geometry>
                <cylinder radius="0.05" length="0.03"/>
            </geometry>
            <material name="black"/>
        </visual>
        <collision>
            <origin xyz="0.0 0.0 0.0" rpy="0.0 0.0 0.0"/>
            <geometry>
                <cylinder radius="0.05" length="0.03"/>
            </geometry>
        </collision>
        <inertial>
            <mass value="0.5"/>
            <inertia ixx="0.1" ixy="0.0" ixz="0.0" iyy="0.1" iyz="0.0" izz="0.1"/>
        </inertial>
    </link>

    <gazebo reference="left_wheel">
        <material>Gazebo/FlatBlack</material>
    </gazebo>

    <!-- RIGHT WHEEL LINK -->
    <joint name="right_wheel_joint" type="continuous">
        <origin xyz="0 -0.161 0" rpy="${pi/2} 0.0 0.0"/>
        <parent link="base_link"/>
        <child link="right_wheel"/>
        <axis xyz="0.0 0.0 -1.0"/>
    </joint> 

    <link name="right_wheel">
        <visual>
            <origin xyz="0.0 0.0 0.0" rpy="0.0 0.0 0.0"/>
            <geometry>
                <cylinder radius="0.05" length="0.03"/>
            </geometry>
            <material name="black"/>
        </visual>
        <collision>
            <origin xyz="0.0 0.0 0.0" rpy="0.0 0.0 0.0"/>
            <geometry>
                <cylinder radius="0.05" length="0.03"/>
            </geometry>
        </collision>
        <inertial>
            <mass value="0.5"/>
            <inertia ixx="0.1" ixy="0.0" ixz="0.0" iyy="0.1" iyz="0.0" izz="0.1"/>
        </inertial>
    </link>

    <gazebo reference="right_wheel">
        <material>Gazebo/FlatBlack</material>
    </gazebo>

    <!-- CASTER_WHEEL -->
    <joint name="caster_wheel_joint" type="continuous">
        <parent link="base_link"/>
        <child link="caster_wheel"/>
        <origin xyz="-0.27 0.0 0.0" rpy="${pi/2} 0.0 0.0"/>        <!--dich 34 - 7 = 27cm theo truc x ke tu tam cua chassis-->
    </joint>

    <link name="caster_wheel">
        <visual>
            <geometry>
                <cylinder radius="0.05" length="0.03"/>
            </geometry>
            <material name="black"/>
        </visual>
        <collision>
            <geometry>
                <cylinder radius="0.05" length="0.03"/>
            </geometry>
        </collision>
        <inertial>
            <mass value="0.5"/>
            <inertia ixx="0.1" ixy="0.0" ixz="0.0" iyy="0.1" iyz="0.0" izz="0.1"/>
        </inertial>
        
    </link>

    <gazebo reference="caster_wheel">
        <material>Gazebo/FlatBlack</material>
        <mu1 value="0.001"/>
        <mu2 value="0.001"/>
    </gazebo>

    <!-- lidar -->
    <joint name="joint_scan" type="fixed">
        <origin xyz="0.0 0.0 0.2" rpy="0.0 0.0 0.0"/>     <!--0.215 = 0.2 + 0.03/2-->
        <parent link="base_link"/>
        <!-- <child link="base_scan"/> -->
        <child link="laser"/>
    </joint>

    <!-- <link name="base_scan"> -->
    <link name="laser">
        <visual>
            <geometry>
                <cylinder radius="0.04" length="0.04"/>
            </geometry>
            <material name="black"/>
        </visual>
        <collision>
            <geometry>
                <cylinder radius="0.04" length="0.04"/>
            </geometry>
        </collision>
        <inertial>
            <mass value="0.2"/>
            <inertia ixx="0.01" ixy="0.0" ixz="0.0" iyy="0.01" iyz="0.0" izz="0.01"/>
        </inertial>
    </link>

    <!-- <gazebo reference="base_scan"> -->
    <gazebo reference="laser">
        <material>Gazebo/FlatBlack</material>
    </gazebo>
       
</robot>